
CondaError: Run 'conda init' before 'conda activate'

Traceback (most recent call last):
  File [35m"/shared/content/run.py"[0m, line [35m15[0m, in [35m<module>[0m
    this_round_variants, df_test, df_sorted_all = [31mevolve_experimental[0m[1;31m([0m
                                                  [31m~~~~~~~~~~~~~~~~~~~[0m[1;31m^[0m
        [1;31mprotein_name,[0m
        [1;31m^^^^^^^^^^^^^[0m
    ...<8 lines>...
        [1;31moutput_dir[0m
        [1;31m^^^^^^^^^^[0m
    [1;31m)[0m
    [1;31m^[0m
  File [35m"/shared/EvolvePro/evolvepro/src/evolve.py"[0m, line [35m451[0m, in [35mevolve_experimental[0m
    embeddings = load_experimental_embeddings(
        embeddings_base_path, embeddings_file_name, rename_WT
    )
  File [35m"/shared/EvolvePro/evolvepro/src/data.py"[0m, line [35m113[0m, in [35mload_experimental_embeddings[0m
    embeddings = pd.read_csv(file_path, index_col=0)
  File [35m"/home/ubuntu/anaconda3/lib/python3.13/site-packages/pandas/io/parsers/readers.py"[0m, line [35m1026[0m, in [35mread_csv[0m
    return _read(filepath_or_buffer, kwds)
  File [35m"/home/ubuntu/anaconda3/lib/python3.13/site-packages/pandas/io/parsers/readers.py"[0m, line [35m620[0m, in [35m_read[0m
    parser = TextFileReader(filepath_or_buffer, **kwds)
  File [35m"/home/ubuntu/anaconda3/lib/python3.13/site-packages/pandas/io/parsers/readers.py"[0m, line [35m1620[0m, in [35m__init__[0m
    self._engine = [31mself._make_engine[0m[1;31m(f, self.engine)[0m
                   [31m~~~~~~~~~~~~~~~~~[0m[1;31m^^^^^^^^^^^^^^^^[0m
  File [35m"/home/ubuntu/anaconda3/lib/python3.13/site-packages/pandas/io/parsers/readers.py"[0m, line [35m1880[0m, in [35m_make_engine[0m
    self.handles = [31mget_handle[0m[1;31m([0m
                   [31m~~~~~~~~~~[0m[1;31m^[0m
        [1;31mf,[0m
        [1;31m^^[0m
    ...<6 lines>...
        [1;31mstorage_options=self.options.get("storage_options", None),[0m
        [1;31m^^^^^^^^^^^^^^^^^^^^^^^^^^^^^^^^^^^^^^^^^^^^^^^^^^^^^^^^^^[0m
    [1;31m)[0m
    [1;31m^[0m
  File [35m"/home/ubuntu/anaconda3/lib/python3.13/site-packages/pandas/io/common.py"[0m, line [35m873[0m, in [35mget_handle[0m
    handle = open(
        handle,
    ...<3 lines>...
        newline="",
    )
[1;35mFileNotFoundError[0m: [35m[Errno 2] No such file or directory: '/shared/content/output/c143_esm2_t48_15B_UR50D.csv'[0m
